ERROR:sc2.main:AI step threw an error
Traceback (most recent call last):
  File "C:\Users\Pyry\AppData\Local\Programs\Python\Python37\lib\site-packages\sc2\main.py", line 118, in _play_game_ai
    await ai.issue_events()
  File "C:\Users\Pyry\AppData\Local\Programs\Python\Python37\lib\site-packages\sc2\bot_ai.py", line 549, in issue_events
    await self._issue_building_complete_event(unit)
  File "C:\Users\Pyry\AppData\Local\Programs\Python\Python37\lib\site-packages\sc2\bot_ai.py", line 566, in _issue_building_complete_event
    await self.on_building_construction_complete(unit)
  File "C:\Users\Pyry\Documents\GitLab\sludgement\bot\main.py", line 85, in on_building_construction_complete
    await self.saturate_gas(unit)
  File "C:\Users\Pyry\Documents\GitLab\sludgement\bot\main.py", line 315, in saturate_gas
    for drone in self.units(DRONE).closer_than(15, unit.position).take(3):
  File "C:\Users\Pyry\AppData\Local\Programs\Python\Python37\lib\site-packages\sc2\units.py", line 89, in take
    assert (not require_all) or len(self) >= n
AssertionError